Workbook

Sheet Question 1
B2: STAGE 1 (Data Cleaning) | E2: We are a part of XYZ Co Pvt Ltd company who is in the business of organizing the sports events at international level. Countries nominate sportsmen from different departments and our team has been given the responsibility to systematize the membership roster and generate different reports as per business requirements.
C5: SHEET | D5: COLUMN | E5: TASK
B6: S No | C6: TASK 1: STANDARDIZING THE DATASET
B7: 1 | C7: SPORTSMEN | D7: Col B | E7: Populate the FULLNAME consisting of the following fields ONLY, in the prescribed format: PREFIX FIRSTNAME LASTNAME. (Note: All UPPERCASE)
B8: 2 | C8: SPORTSMEN | D8: Col K | E8: Get the COUNTRY NAME to which these sportsmen belong to. Make use of LOCATION sheet to get the required data
B9: 3 | C9: SPORTSMEN | D9: Col L | E9: Populate the LANGUAGE spoken by the sportsmen. Make use of LOCATION sheet to get the required data
B10: 4 | C10: SPORTSMEN | D10: Col M | E10: Generate the EMAIL ADDRESS for those members, who speak English, in the prescribed format : lastname.firstname@xyz.org (Note: All lowercase) and for all other members, format should be lastname.firstname@xyz.com (Note: All lowercase)
B11: 5 | C11: SPORTSMEN | D11: Col Q | E11: Populate the SPORT LOCATION of the sport played by each player. Make use of SPORT sheet to get the required data
B13: S No | C13: TASK 2: DATA FORMATTING
B14: 1 | C14: SPORTSMEN | D14: Col A | E14: Display MEMBER ID as always 3 digit number (Note: 001, 002…, 020,… etc)
B15: 2 | C15: SPORTSMEN | D15: Col G | E15: Format the BIRTHDATE as dd mmm' yyyy (Prescribed format example: 09 May' 1986)
B16: 3 | C16: SPORTSMEN | D16: Col N | E16: Display the units for the WEIGHT column (Prescribed format example: 80 kg)
B17: 4 | C17: SPORTSMEN | D17: Col S | E17: Format the SALARY to show the data in thousands. If SALARY is less than 100,000 then display data with 2 decimal places else display data with one decimal place. In both cases units should be thousands (k) e.g. 87670 --> 87.67 k and 123250 --> 123.2 k

Sheet Question 2
B2: STAGE 2 (Data Analysis) | E2: We are a part of XYZ Co Pvt Ltd company who is in the business of organizing the sports events at international level. Countries nominate sportsmen from different departments and our team has been given the responsibility to systematize the membership roster and generate different reports as per business requirements.
B5: Instructions: Make use of data from SPORTSMEN worksheet after attempting Question 1
C6: SHEET | D6: RANGE | E6: TASK
B7: S No | C7: TASK 1: SUMMARIZE DATA - PIVOT TABLE
B8: 1 | C8: ANALYSIS | D8: Range B3 | E8: Create a PIVOT table in the worksheet ANALYSIS, starting at cell B3, with the following details:
B9: 2 | C9: ANALYSIS | E9: In COLUMNS; Group : GENDER.
B10: 3 | C10: ANALYSIS | E10: In ROWS; Group : COUNTRY (Note: use COUNTRY NAMES)
B11: 4 | C11: ANALYSIS | E11: In VALUES; Calculate the count of candidates from each COUNTRY and GENDER type
B12: 5 | C12: ANALYSIS | E12: Remove GRAND TOTALs
B14: S No | C14: TASK 2: SUMMARIZE DATA - EXCEL FUNCTIONS
B15: 1 | C15: ANALYSIS | D15: Range G4 | E15: Create a SUMMARY table in the worksheet ANALYSIS, starting at cell G4, with the following details.
B16: 2 | C16: ANALYSIS | D16: Range H4:I4 | E16: Starting from range RANGE H4; get the distinct GENDER. Use remove duplicates option and transpose the data
B17: 3 | C17: ANALYSIS | D17: Range G5:G16 | E17: Starting from range RANGE G5; get the distinct COUNTRY (Note: use COUNTRY NAMES)
B18: 4 | C18: ANALYSIS | D18: Range H5:I16 | E18: In the cross table, get the count of candidates from each COUNTRY and GENDER type

Sheet Question 3
B2: STAGE 3 (Generate Report) | E2: We are a part of XYZ Co Pvt Ltd company who is in the business of organizing the sports events at international level. Countries nominate sportsmen from different departments and our team has been given the responsibility to systematize the membership roster and generate different reports as per business requirements.
B5: Instructions: Make use of data from SPORTSMEN worksheet after attempting Question 1
C6: SHEET | D6: RANGE | E6: TASK
B7: S No | C7: GENERATE REPORT - PIVOT TABLE
B8: 1 | C8: REPORT | D8: Range A3 | E8: Create a PIVOT table report in the worksheet REPORT, starting at cell A3, with the following information.
B9: 2 | C9: REPORT | E9: Report should contain MEMBER ID, FULL NAME, EMAIL, GENDER, YEAR OF BIRTH (Note: don't display quarters, months and dates), COUNTRY NAME, LANGUAGE and SPORT played by them
B10: 3 | C10: REPORT | E10: Change the report layout to TABULAR form
B11: 4 | C11: REPORT | E11: Remove expand and collapse buttons
B12: 5 | C12: REPORT | E12: Remove GRAND TOTALs
B13: 5 | C13: REPORT | D13: Range A1 | E13: Allow user to filter the data by SPORT LOCATION

Sheet ANALYSIS
B3: Count of GENDER | C3: Column Labels
B4: Row Labels | C4: Female | D4: Male | E4: Grand Total | H4: GENDER
B5: ARGENTINA | C5: 1 | D5: 2 | E5: 3 | G5: COUNTRY NAME | H5: Female | I5: Male
B6: AUSTRALIA | C6: 6 | D6: 2 | E6: 8 | G6: USA | H6: =COUNTIFS(SPORTSMEN!$K$1:$K$51,$G6,SPORTSMEN!$I$1:$I$51,ANALYSIS!H$5) -> 4 | I6: =COUNTIFS(SPORTSMEN!$K$1:$K$51,$G6,SPORTSMEN!$I$1:$I$51,ANALYSIS!I$5) -> 3
B7: AUSTRIA | C7: 1 | D7: 2 | E7: 3 | G7: BRAZIL | H7: =COUNTIFS(SPORTSMEN!$K$1:$K$51,$G7,SPORTSMEN!$I$1:$I$51,ANALYSIS!H$5) -> 0 | I7: =COUNTIFS(SPORTSMEN!$K$1:$K$51,$G7,SPORTSMEN!$I$1:$I$51,ANALYSIS!I$5) -> 2
B8: BRAZIL | D8: 2 | E8: 2 | G8: UK | H8: =COUNTIFS(SPORTSMEN!$K$1:$K$51,$G8,SPORTSMEN!$I$1:$I$51,ANALYSIS!H$5) -> 3 | I8: =COUNTIFS(SPORTSMEN!$K$1:$K$51,$G8,SPORTSMEN!$I$1:$I$51,ANALYSIS!I$5) -> 2
B9: FRANCE | C9: 3 | D9: 6 | E9: 9 | G9: GERMANY | H9: =COUNTIFS(SPORTSMEN!$K$1:$K$51,$G9,SPORTSMEN!$I$1:$I$51,ANALYSIS!H$5) -> 1 | I9: =COUNTIFS(SPORTSMEN!$K$1:$K$51,$G9,SPORTSMEN!$I$1:$I$51,ANALYSIS!I$5) -> 4
B10: GERMANY | C10: 1 | D10: 4 | E10: 5 | G10: AUSTRALIA | H10: =COUNTIFS(SPORTSMEN!$K$1:$K$51,$G10,SPORTSMEN!$I$1:$I$51,ANALYSIS!H$5) -> 6 | I10: =COUNTIFS(SPORTSMEN!$K$1:$K$51,$G10,SPORTSMEN!$I$1:$I$51,ANALYSIS!I$5) -> 2
B11: NETHERLANDS | C11: 2 | D11: 1 | E11: 3 | G11: AUSTRIA | H11: =COUNTIFS(SPORTSMEN!$K$1:$K$51,$G11,SPORTSMEN!$I$1:$I$51,ANALYSIS!H$5) -> 1 | I11: =COUNTIFS(SPORTSMEN!$K$1:$K$51,$G11,SPORTSMEN!$I$1:$I$51,ANALYSIS!I$5) -> 2
B12: SPAIN | C12: 3 | E12: 3 | G12: FRANCE | H12: =COUNTIFS(SPORTSMEN!$K$1:$K$51,$G12,SPORTSMEN!$I$1:$I$51,ANALYSIS!H$5) -> 3 | I12: =COUNTIFS(SPORTSMEN!$K$1:$K$51,$G12,SPORTSMEN!$I$1:$I$51,ANALYSIS!I$5) -> 6
B13: SWEDEN | C13: 1 | D13: 1 | E13: 2 | G13: ARGENTINA | H13: =COUNTIFS(SPORTSMEN!$K$1:$K$51,$G13,SPORTSMEN!$I$1:$I$51,ANALYSIS!H$5) -> 1 | I13: =COUNTIFS(SPORTSMEN!$K$1:$K$51,$G13,SPORTSMEN!$I$1:$I$51,ANALYSIS!I$5) -> 2
B14: UK | C14: 3 | D14: 2 | E14: 5 | G14: SPAIN | H14: =COUNTIFS(SPORTSMEN!$K$1:$K$51,$G14,SPORTSMEN!$I$1:$I$51,ANALYSIS!H$5) -> 3 | I14: =COUNTIFS(SPORTSMEN!$K$1:$K$51,$G14,SPORTSMEN!$I$1:$I$51,ANALYSIS!I$5) -> 0
B15: USA | C15: 4 | D15: 3 | E15: 7 | G15: NETHERLANDS | H15: =COUNTIFS(SPORTSMEN!$K$1:$K$51,$G15,SPORTSMEN!$I$1:$I$51,ANALYSIS!H$5) -> 2 | I15: =COUNTIFS(SPORTSMEN!$K$1:$K$51,$G15,SPORTSMEN!$I$1:$I$51,ANALYSIS!I$5) -> 1
B16: Grand Total | C16: 25 | D16: 25 | E16: 50 | G16: SWEDEN | H16: =COUNTIFS(SPORTSMEN!$K$1:$K$51,$G16,SPORTSMEN!$I$1:$I$51,ANALYSIS!H$5) -> 1 | I16: =COUNTIFS(SPORTSMEN!$K$1:$K$51,$G16,SPORTSMEN!$I$1:$I$51,ANALYSIS!I$5) -> 1

Sheet REPORT
A1: SPORT LOCATION | B1: (All)
A3: Row Labels
A4: 1
A5: MS. ANNIE ABBOTT
A6: Abbott.Annie@xyzorg
A7: 1997
A8: Female
A9: 35699
A10: English
A11: USA
A12: Cycling Track
A13: 2
A14: MS. AURELIE LIESUCHKE
A15: Liesuchke.Aurelie@xyzorg
A16: 1992
A17: Female
A18: 33641
A19: English
A20: USA
A21: Boxing
A22: 3
A23: SR. TOMAS FILHO
A24: Filho.Tomas@xyz.com
A25: 1969
A26: Male
A27: 25394
A28: Portuguese
A29: BRAZIL
A30: Football
A31: 4
A32: MS. DARBY CRUICKSHANK
A33: Cruickshank.Darby@xyzorg
A34: 1975
A35: Female
A36: 27532
A37: English
A38: USA
A39: Alpine Skiing
A40: 5
A41: DR. JAYDON BORER
...

Sheet SPORTSMEN
A1: MEMBER ID | B1: FULL NAME | C1: PREFIX | D1: FIRSTNAME | E1: MIDDLENAME | F1: LASTNAME | G1: BIRTHDATE | H1: ZODIAC | I1: GENDER | J1: COUNTRYCODE | K1: COUNTRY NAME | L1: LANGUAGE | M1: EMAIL | N1: WEIGHT | O1: EYECOLOR | P1: BLOODTYPE | Q1: SPORT LOCATION | R1: SPORTS | S1: SALARY | T1: FULLNAME (UPPERCASE) | U1: MEMBER ID | V1: BIRTHDATE | W1: WEIGHT | X1: SALARY
A2: 1 | B2: =UPPER(_xlfn.CONCAT(C2," ",D2," ",F2)) -> MS. ANNIE ABBOTT | C2: Ms. | D2: Annie | F2: Abbott | G2: 35699 | H2: Libra | I2: Female | J2: US | K2: =HLOOKUP($J2,LOCATION!$A$2:$M$3,2,0) -> USA | L2: =INDEX(LOCATION!$A$1:$M$1,1,MATCH($J2,LOCATION!$A$2:$M$2,0)) -> English | M2: =_xlfn.CONCAT(F2,".",D2,"@xyz",IF(L2="English","org",".com")) -> Abbott.Annie@xyzorg | N2: 94 | O2: Green | P2: A− | Q2: =_xlfn.XLOOKUP($R2,SPORT!$B$1:$B$33,SPORT!$A$1:$A$33) -> INDOOR | R2: Cycling Track | S2: 80727 | T2: =UPPER(B2) -> MS. ANNIE ABBOTT | U2: 1 | V2: 35699 | W2: 94 | X2: 80727
A3: 2 | B3: =UPPER(_xlfn.CONCAT(C3," ",D3," ",F3)) -> MS. AURELIE LIESUCHKE | C3: Ms. | D3: Aurelie | F3: Liesuchke | G3: 33641 | H3: Aquarius | I3: Female | J3: US | K3: =HLOOKUP($J3,LOCATION!$A$2:$M$3,2,0) -> USA | L3: =INDEX(LOCATION!$A$1:$M$1,1,MATCH($J3,LOCATION!$A$2:$M$2,0)) -> English | M3: =_xlfn.CONCAT(F3,".",D3,"@xyz",IF(L3="English","org",".com")) -> Liesuchke.Aurelie@xyzorg | N3: 84.2 | O3: Brown | P3: O− | Q3: =_xlfn.XLOOKUP($R3,SPORT!$B$1:$B$33,SPORT!$A$1:$A$33) -> INDOOR | R3: Boxing | S3: 87471 | T3: =UPPER(B3) -> MS. AURELIE LIESUCHKE | U3: 2 | V3: 33641 | W3: 84.2 | X3: 87471
A4: 3 | B4: =UPPER(_xlfn.CONCAT(C4," ",D4," ",F4)) -> SR. TOMAS FILHO | C4: Sr. | D4: Tomas | E4: Ferreira | F4: Filho | G4: 25394 | H4: Cancer | I4: Male | J4: BR | K4: =HLOOKUP($J4,LOCATION!$A$2:$M$3,2,0) -> BRAZIL | L4: =INDEX(LOCATION!$A$1:$M$1,1,MATCH($J4,LOCATION!$A$2:$M$2,0)) -> Portuguese | M4: =_xlfn.CONCAT(F4,".",D4,"@xyz",IF(L4="English","org",".com")) -> Filho.Tomas@xyz.com | N4: 52.9 | O4: Amber | P4: A− | Q4: =_xlfn.XLOOKUP($R4,SPORT!$B$1:$B$33,SPORT!$A$1:$A$33) -> OUTDOOR | R4: Football | S4: 64724 | T4: =UPPER(B4) -> SR. TOMAS FILHO | U4: 3 | V4: 25394 | W4: 52.9 | X4: 64724
A5: 4 | B5: =UPPER(_xlfn.CONCAT(C5," ",D5," ",F5)) -> MS. DARBY CRUICKSHANK | C5: Ms. | D5: Darby | F5: Cruickshank | G5: 27532 | H5: Taurus | I5: Female | J5: US | K5: =HLOOKUP($J5,LOCATION!$A$2:$M$3,2,0) -> USA | L5: =INDEX(LOCATION!$A$1:$M$1,1,MATCH($J5,LOCATION!$A$2:$M$2,0)) -> English | M5: =_xlfn.CONCAT(F5,".",D5,"@xyz",IF(L5="English","org",".com")) -> Cruickshank.Darby@xyzorg | N5: 48.9 | O5: Green | P5: O− | Q5: =_xlfn.XLOOKUP($R5,SPORT!$B$1:$B$33,SPORT!$A$1:$A$33) -> OUTDOOR | R5: Alpine Skiing | S5: 110823 | T5: =UPPER(B5) -> MS. DARBY CRUICKSHANK | U5: 4 | V5: 27532 | W5: 48.9 | X5: 110823
A6: 5 | B6: =UPPER(_xlfn.CONCAT(C6," ",D6," ",F6)) -> DR. JAYDON BORER | C6: Dr. | D6: Jaydon | F6: Borer | G6: 25706 | H6: Taurus | I6: Male | J6: US | K6: =HLOOKUP($J6,LOCATION!$A$2:$M$3,2,0) -> USA | L6: =INDEX(LOCATION!$A$1:$M$1,1,MATCH($J6,LOCATION!$A$2:$M$2,0)) -> English | M6: =_xlfn.CONCAT(F6,".",D6,"@xyz",IF(L6="English","org",".com")) -> Borer.Jaydon@xyzorg | N6: 84.8 | O6: Blue | P6: B− | Q6: =_xlfn.XLOOKUP($R6,SPORT!$B$1:$B$33,SPORT!$A$1:$A$33) -> INDOOR | R6: Water Polo | S6: 56916 | T6: =UPPER(B6) -> DR. JAYDON BORER | U6: 5 | V6: 25706 | W6: 84.8 | X6: 56916
A7: 6 | B7: =UPPER(_xlfn.CONCAT(C7," ",D7," ",F7)) -> MR. MORIAH LYNCH | C7: Mr. | D7: Moriah | F7: Lynch | G7: 33944 | H7: Sagittarius | I7: Male | J7: US | K7: =HLOOKUP($J7,LOCATION!$A$2:$M$3,2,0) -> USA | L7: =INDEX(LOCATION!$A$1:$M$1,1,MATCH($J7,LOCATION!$A$2:$M$2,0)) -> English | M7: =_xlfn.CONCAT(F7,".",D7,"@xyz",IF(L7="English","org",".com")) -> Lynch.Moriah @xyzorg | N7: 83.2 | O7: Blue | P7: O− | Q7: =_xlfn.XLOOKUP($R7,SPORT!$B$1:$B$33,SPORT!$A$1:$A$33) -> INDOOR | R7: Fencing | S7: 51133 | T7: =UPPER(B7) -> MR. MORIAH LYNCH | U7: 6 | V7: 33944 | W7: 83.2 | X7: 51133
A8: 7 | B8: =UPPER(_xlfn.CONCAT(C8," ",D8," ",F8)) -> MS. AMIYA EICHMANN | C8: Ms. | D8: Amiya | F8: Eichmann | G8: 36370 | H8: Leo | I8: Female | J8: US | K8: =HLOOKUP($J8,LOCATION!$A$2:$M$3,2,0) -> USA | L8: =INDEX(LOCATION!$A$1:$M$1,1,MATCH($J8,LOCATION!$A$2:$M$2,0)) -> English | M8: =_xlfn.CONCAT(F8,".",D8,"@xyz",IF(L8="English","org",".com")) -> Eichmann.Amiya@xyzorg | N8: 61.1 | O8: Blue | P8: B− | Q8: =_xlfn.XLOOKUP($R8,SPORT!$B$1:$B$33,SPORT!$A$1:$A$33) -> OUTDOOR | R8: Cycling Road | S8: 65465 | T8: =UPPER(B8) -> MS. AMIYA EICHMANN | U8: 7 | V8: 36370 | W8: 61.1 | X8: 65465
A9: 8 | B9: =UPPER(_xlfn.CONCAT(C9," ",D9," ",F9)) -> MR. PIERCE RAU | C9: Mr. | D9: Pierce | F9: Rau | G9: 23141 | H9: Taurus | I9: Male | J9: US | K9: =HLOOKUP($J9,LOCATION!$A$2:$M$3,2,0) -> USA | L9: =INDEX(LOCATION!$A$1:$M$1,1,MATCH($J9,LOCATION!$A$2:$M$2,0)) -> English | M9: =_xlfn.CONCAT(F9,".",D9,"@xyz",IF(L9="English","org",".com")) -> Rau.Pierce@xyzorg | N9: 105.7 | O9: Amber | P9: A+ | Q9: =_xlfn.XLOOKUP($R9,SPORT!$B$1:$B$33,SPORT!$A$1:$A$33) -> INDOOR | R9: Curling | S9: 109885 | T9: =UPPER(B9) -> MR. PIERCE RAU | U9: 8 | V9: 23141 | W9: 105.7 | X9: 109885
A10: 9 | B10: =UPPER(_xlfn.CONCAT(C10," ",D10," ",F10)) -> MS. AMELIA STEVENS | C10: Ms. | D10: Amelia | F10: Stevens | G10: 25965 | H10: Aquarius | I10: Female | J10: GB | K10: =HLOOKUP($J10,LOCATION!$A$2:$M$3,2,0) -> UK | L10: =INDEX(LOCATION!$A$1:$M$1,1,MATCH($J10,LOCATION!$A$2:$M$2,0)) -> English | M10: =_xlfn.CONCAT(F10,".",D10,"@xyz",IF(L10="English","org",".com")) -> Stevens.Amelia@xyzorg | N10: 65.3 | O10: Blue | P10: A+ | Q10: =_xlfn.XLOOKUP($R10,SPORT!$B$1:$B$33,SPORT!$A$1:$A$33) -> INDOOR | R10: Shooting | S10: 60061 | T10: =UPPER(B10) -> MS. AMELIA STEVENS | U10: 9 | V10: 25965 | W10: 65.3 | X10: 60061
A11: 10 | B11: =UPPER(_xlfn.CONCAT(C11," ",D11," ",F11)) -> MR. TOBY SIMPSON | C11: Mr. | D11: Toby | F11: Simpson | G11: 23732 | H11: Sagittarius | I11: Male | J11: GB | K11: =HLOOKUP($J11,LOCATION!$A$2:$M$3,2,0) -> UK | L11: =INDEX(LOCATION!$A$1:$M$1,1,MATCH($J11,LOCATION!$A$2:$M$2,0)) -> English | M11: =_xlfn.CONCAT(F11,".",D11,"@xyz",IF(L11="English","org",".com")) -> Simpson.Toby@xyzorg | N11: 62.9 | O11: Amber | P11: O+ | Q11: =_xlfn.XLOOKUP($R11,SPORT!$B$1:$B$33,SPORT!$A$1:$A$33) -> OUTDOOR | R11: Cycling Road | S11: 32758 | T11: =UPPER(B11) -> MR. TOBY SIMPSON | U11: 10 | V11: 23732 | W11: 62.9 | X11: 32758
A12: 11 | B12: =UPPER(_xlfn.CONCAT(C12," ",D12," ",F12)) -> SIR ETHAN MURPHY | C12: Sir | D12: Ethan | F12: Murphy | G12: 31733 | H12: Scorpio | I12: Male | J12: GB | K12: =HLOOKUP($J12,LOCATION!$A$2:$M$3,2,0) -> UK | L12: =INDEX(LOCATION!$A$1:$M$1,1,MATCH($J12,LOCATION!$A$2:$M$2,0)) -> English | M12: =_xlfn.CONCAT(F12,".",D12,"@xyz",IF(L12="English","org",".com")) -> Murphy.Ethan@xyzorg | N12: 104.3 | O12: Brown | P12: O+ | Q12: =_xlfn.XLOOKUP($R12,SPORT!$B$1:$B$33,SPORT!$A$1:$A$33) -> OUTDOOR | R12: Freestyle Skiing | S12: 99613 | T12: =UPPER(B12) -> SIR ETHAN MURPHY | U12: 11 | V12: 31733 | W12: 104.3 | X12: 99613
A13: 12 | B13: =UPPER(_xlfn.CONCAT(C13," ",D13," ",F13)) -> MRS. ASHLEY WOOD | C13: Mrs. | D13: Ashley | F13: Wood | G13: 28412 | H13: Libra | I13: Female | J13: GB | K13: =HLOOKUP($J13,LOCATION!$A$2:$M$3,2,0) -> UK | L13: =INDEX(LOCATION!$A$1:$M$1,1,MATCH($J13,LOCATION!$A$2:$M$2,0)) -> English | M13: =_xlfn.CONCAT(F13,".",D13,"@xyz",IF(L13="English","org",".com")) -> Wood.Ashley@xyzorg | N13: 100.7 | O13: Brown | P13: O+ | Q13: =_xlfn.XLOOKUP($R13,SPORT!$B$1:$B$33,SPORT!$A$1:$A$33) -> OUTDOOR | R13: Archery | S13: 56595 | T13: =UPPER(B13) -> MRS. ASHLEY WOOD | U13: 12 | V13: 28412 | W13: 100.7 | X13: 56595
A14: 13 | B14: =UPPER(_xlfn.CONCAT(C14," ",D14," ",F14)) -> MS. MEGAN SCOTT | C14: Ms. | D14: Megan | F14: Scott | G14: 28168 | H14: Aquarius | I14: Female | J14: GB | K14: =HLOOKUP($J14,LOCATION!$A$2:$M$3,2,0) -> UK | L14: =INDEX(LOCATION!$A$1:$M$1,1,MATCH($J14,LOCATION!$A$2:$M$2,0)) -> English | M14: =_xlfn.CONCAT(F14,".",D14,"@xyz",IF(L14="English","org",".com")) -> Scott.Megan@xyzorg | N14: 70.9 | O14: Green | P14: A− | Q14: =_xlfn.XLOOKUP($R14,SPORT!$B$1:$B$33,SPORT!$A$1:$A$33) -> OUTDOOR | R14: Rugby | S14: 117408 | T14: =UPPER(B14) -> MS. MEGAN SCOTT | U14: 13 | V14: 28168 | W14: 70.9 | X14: 117408
A15: 14 | B15: =UPPER(_xlfn.CONCAT(C15," ",D15," ",F15)) -> HR. HELMUT WEINHAE | C15: Hr. | D15: Helmut | F15: Weinhae | G15: 21788 | H15: Virgo | I15: Male | J15: DE | K15: =HLOOKUP($J15,LOCATION!$A$2:$M$3,2,0) -> GERMANY | L15: =INDEX(LOCATION!$A$1:$M$1,1,MATCH($J15,LOCATION!$A$2:$M$2,0)) -> German | M15: =_xlfn.CONCAT(F15,".",D15,"@xyz",IF(L15="English","org",".com")) -> Weinhae.Helmut@xyz.com | N15: 68.3 | O15: Gray | P15: A+ | Q15: =_xlfn.XLOOKUP($R15,SPORT!$B$1:$B$33,SPORT!$A$1:$A$33) -> OUTDOOR | R15: Canoe Sprint | S15: 64862 | T15: =UPPER(B15) -> HR. HELMUT WEINHAE | U15: 14 | V15: 21788 | W15: 68.3 | X15: 64862
A16: 15 | B16: =UPPER(_xlfn.CONCAT(C16," ",D16," ",F16)) -> PROF. MILENA SCHOTIN | C16: Prof. | D16: Milena | F16: Schotin | G16: 23804 | H16: Pisces | I16: Female | J16: DE | K16: =HLOOKUP($J16,LOCATION!$A$2:$M$3,2,0) -> GERMANY | L16: =INDEX(LOCATION!$A$1:$M$1,1,MATCH($J16,LOCATION!$A$2:$M$2,0)) -> German | M16: =_xlfn.CONCAT(F16,".",D16,"@xyz",IF(L16="English","org",".com")) -> Schotin.Milena@xyz.com | N16: 105.3 | O16: Gray | P16: O+ | Q16: =_xlfn.XLOOKUP($R16,SPORT!$B$1:$B$33,SPORT!$A$1:$A$33) -> INDOOR | R16: Cycling BMX | S16: 10241 | T16: =UPPER(B16) -> PROF. MILENA SCHOTIN | U16: 15 | V16: 23804 | W16: 105.3 | X16: 10241
... A39: 38 | B39: =UPPER(_xlfn.CONCAT(C39," ",D39," ",F39)) -> M. BERNARD HOARAU-GUYON | C39: M. | D39: Bernard | F39: Hoarau-Guyon | G39: 30327 | H39: Capricorn | I39: Male | J39: FR | K39: =HLOOKUP($J39,LOCATION!$A$2:$M$3,2,0) -> FRANCE | L39: =INDEX(LOCATION!$A$1:$M$1,1,MATCH($J39,LOCATION!$A$2:$M$2,0)) -> French | M39: =_xlfn.CONCAT(F39,".",D39,"@xyz",IF(L39="English","org",".com")) -> Hoarau-Guyon.Bernard@xyz.com | N39: 59.7 | O39: Gray | P39: O− | Q39: =_xlfn.XLOOKUP($R39,SPORT!$B$1:$B$33,SPORT!$A$1:$A$33) -> INDOOR | R39: Cycling Track | S39: 71352 | T39: =UPPER(B39) -> M. BERNARD HOARAU-GUYON | U39: 38 | V39: 30327 | W39: 59.7 | X39: 86262
A40: 39 | B40: =UPPER(_xlfn.CONCAT(C40," ",D40," ",F40)) -> SR. HIDALGO TERCERO | C40: Sr. | D40: Hidalgo | E40: Cantu | F40: Tercero | G40: 31016 | H40: Sagittarius | I40: Male | J40: AG | K40: =HLOOKUP($J40,LOCATION!$A$2:$M$3,2,0) -> ARGENTINA | L40: =INDEX(LOCATION!$A$1:$M$1,1,MATCH($J40,LOCATION!$A$2:$M$2,0)) -> Spanish | M40: =_xlfn.CONCAT(F40,".",D40,"@xyz",IF(L40="English","org",".com")) -> Tercero.Hidalgo@xyz.com | N40: 77.7 | O40: Gray | P40: B− | Q40: =_xlfn.XLOOKUP($R40,SPORT!$B$1:$B$33,SPORT!$A$1:$A$33) -> OUTDOOR | R40: Canoe Slalom | S40: 116376 | T40: =UPPER(B40) -> SR. HIDALGO TERCERO | U40: 39 | V40: 31016 | W40: 77.7 | X40: 86262
A41: 40 | B41: =UPPER(_xlfn.CONCAT(C41," ",D41," ",F41)) -> SR. HADALGO POLANCO | C41: Sr. | D41: Hadalgo | F41: Polanco | G41: 32314 | H41: Gemini | I41: Male | J41: AG | K41: =HLOOKUP($J41,LOCATION!$A$2:$M$3,2,0) -> ARGENTINA | L41: =INDEX(LOCATION!$A$1:$M$1,1,MATCH($J41,LOCATION!$A$2:$M$2,0)) -> Spanish | M41: =_xlfn.CONCAT(F41,".",D41,"@xyz",IF(L41="English","org",".com")) -> Polanco.Hadalgo@xyz.com | N41: 98 | O41: Blue | P41: A− | Q41: =_xlfn.XLOOKUP($R41,SPORT!$B$1:$B$33,SPORT!$A$1:$A$33) -> OUTDOOR | R41: Beach Volleyball | S41: 114144 | T41: =UPPER(B41) -> SR. HADALGO POLANCO | U41: 40 | V41: 32314 | W41: 98 | X41: 86262
A42: 41 | B42: =UPPER(_xlfn.CONCAT(C42," ",D42," ",F42)) -> SRA. LAURA OLIVIERA | C42: Sra. | D42: Laura | F42: Oliviera | G42: 27076 | H42: Aquarius | I42: Female | J42: AG | K42: =HLOOKUP($J42,LOCATION!$A$2:$M$3,2,0) -> ARGENTINA | L42: =INDEX(LOCATION!$A$1:$M$1,1,MATCH($J42,LOCATION!$A$2:$M$2,0)) -> Spanish | M42: =_xlfn.CONCAT(F42,".",D42,"@xyz",IF(L42="English","org",".com")) -> Oliviera.Laura@xyz.com | N42: 51.9 | O42: Amber | P42: O− | Q42: =_xlfn.XLOOKUP($R42,SPORT!$B$1:$B$33,SPORT!$A$1:$A$33) -> OUTDOOR | R42: Athletics | S42: 79872 | T42: =UPPER(B42) -> SRA. LAURA OLIVIERA | U42: 41 | V42: 27076 | W42: 51.9 | X42: 86262
A43: 42 | B43: =UPPER(_xlfn.CONCAT(C43," ",D43," ",F43)) -> SRA. AINHOA GARZA | C43: Sra. | D43: Ainhoa | F43: Garza | G43: 32941 | H43: Pisces | I43: Female | J43: ES | K43: =HLOOKUP($J43,LOCATION!$A$2:$M$3,2,0) -> SPAIN | L43: =INDEX(LOCATION!$A$1:$M$1,1,MATCH($J43,LOCATION!$A$2:$M$2,0)) -> Spanish | M43: =_xlfn.CONCAT(F43,".",D43,"@xyz",IF(L43="English","org",".com")) -> Garza.Ainhoa@xyz.com | N43: 55.6 | O43: Brown | P43: O+ | Q43: =_xlfn.XLOOKUP($R43,SPORT!$B$1:$B$33,SPORT!$A$1:$A$33) -> INDOOR | R43: Gymnastics Artistic | S43: 101969 | T43: =UPPER(B43) -> SRA. AINHOA GARZA | U43: 42 | V43: 32941 | W43: 55.6 | X43: 86262
A44: 43 | B44: =UPPER(_xlfn.CONCAT(C44," ",D44," ",F44)) -> SRA. ISABEL BANDA | C44: Sra. | D44: Isabel | F44: Banda | G44: 21927 | H44: Capricorn | I44: Female | J44: ES | K44: =HLOOKUP($J44,LOCATION!$A$2:$M$3,2,0) -> SPAIN | L44: =INDEX(LOCATION!$A$1:$M$1,1,MATCH($J44,LOCATION!$A$2:$M$2,0)) -> Spanish | M44: =_xlfn.CONCAT(F44,".",D44,"@xyz",IF(L44="English","org",".com")) -> Banda.Isabel@xyz.com | N44: 102.3 | O44: Amber | P44: O+ | Q44: =_xlfn.XLOOKUP($R44,SPORT!$B$1:$B$33,SPORT!$A$1:$A$33) -> OUTDOOR | R44: Canoe Slalom | S44: 50659 | T44: =UPPER(B44) -> SRA. ISABEL BANDA | U44: 43 | V44: 21927 | W44: 102.3 | X44: 86262
A45: 44 | B45: =UPPER(_xlfn.CONCAT(C45," ",D45," ",F45)) -> SRA. CAROLOTA MATEOS | C45: Sra. | D45: Carolota | F45: Mateos | G45: 23952 | H45: Leo | I45: Female | J45: ES | K45: =HLOOKUP($J45,LOCATION!$A$2:$M$3,2,0) -> SPAIN | L45: =INDEX(LOCATION!$A$1:$M$1,1,MATCH($J45,LOCATION!$A$2:$M$2,0)) -> Spanish | M45: =_xlfn.CONCAT(F45,".",D45,"@xyz",IF(L45="English","org",".com")) -> Mateos.Carolota@xyz.com | N45: 58.8 | O45: Gray | P45: O− | Q45: =_xlfn.XLOOKUP($R45,SPORT!$B$1:$B$33,SPORT!$A$1:$A$33) -> OUTDOOR | R45: Athletics | S45: 58215 | T45: =UPPER(B45) -> SRA. CAROLOTA MATEOS | U45: 44 | V45: 23952 | W45: 58.8 | X45: 86262
A46: 45 | B46: =UPPER(_xlfn.CONCAT(C46," ",D46," ",F46)) -> MW. ELIZE PRINS | C46: Mw. | D46: Elize | F46: Prins | G46: 22044 | H46: Taurus | I46: Female | J46: DU | K46: =HLOOKUP($J46,LOCATION!$A$2:$M$3,2,0) -> NETHERLANDS | L46: =INDEX(LOCATION!$A$1:$M$1,1,MATCH($J46,LOCATION!$A$2:$M$2,0)) -> Dutch | M46: =_xlfn.CONCAT(F46,".",D46,"@xyz",IF(L46="English","org",".com")) -> Prins.Elize@xyz.com | N46: 63.8 | O46: Blue | P46: O+ | Q46: =_xlfn.XLOOKUP($R46,SPORT!$B$1:$B$33,SPORT!$A$1:$A$33) -> INDOOR | R46: Judo | S46: 39935 | T46: =UPPER(B46) -> MW. ELIZE PRINS | U46: 45 | V46: 22044 | W46: 63.8 | X46: 39935
A47: 46 | B47: =UPPER(_xlfn.CONCAT(C47," ",D47," ",F47)) -> DHR. RYAN PHAM | C47: dhr. | D47: Ryan | F47: Pham | G47: 26940 | H47: Libra | I47: Male | J47: DU | K47: =HLOOKUP($J47,LOCATION!$A$2:$M$3,2,0) -> NETHERLANDS | L47: =INDEX(LOCATION!$A$1:$M$1,1,MATCH($J47,LOCATION!$A$2:$M$2,0)) -> Dutch | M47: =_xlfn.CONCAT(F47,".",D47,"@xyz",IF(L47="English","org",".com")) -> Pham.Ryan@xyz.com | N47: 98.6 | O47: Amber | P47: B+ | Q47: =_xlfn.XLOOKUP($R47,SPORT!$B$1:$B$33,SPORT!$A$1:$A$33) -> OUTDOOR | R47: Beach Volleyball | S47: 44865 | T47: =UPPER(B47) -> DHR. RYAN PHAM | U47: 46 | V47: 26940 | W47: 98.6 | X47: 44865
A48: 47 | B48: =UPPER(_xlfn.CONCAT(C48," ",D48," ",F48)) -> MW ELISE ROTTEVEEL | C48: Mw | D48: Elise | F48: Rotteveel | G48: 24936 | H48: Aries | I48: Female | J48: DU | K48: =HLOOKUP($J48,LOCATION!$A$2:$M$3,2,0) -> NETHERLANDS | L48: =INDEX(LOCATION!$A$1:$M$1,1,MATCH($J48,LOCATION!$A$2:$M$2,0)) -> Dutch | M48: =_xlfn.CONCAT(F48,".",D48,"@xyz",IF(L48="English","org",".com")) -> Rotteveel.Elise@xyz.com | N48: 61.8 | O48: Gray | P48: O− | Q48: =_xlfn.XLOOKUP($R48,SPORT!$B$1:$B$33,SPORT!$A$1:$A$33) -> OUTDOOR | R48: Beach Volleyball | S48: 90478 | T48: =UPPER(B48) -> MW ELISE ROTTEVEEL | U48: 47 | V48: 24936 | W48: 61.8 | X48: 90478
A49: 48 | B49: =UPPER(_xlfn.CONCAT(C49," ",D49," ",F49)) -> FRU. MIRJAM SODERBERG | C49: Fru. | D49: Mirjam | F49: Soderberg | G49: 35567 | H49: Taurus | I49: Female | J49: SV | K49: =HLOOKUP($J49,LOCATION!$A$2:$M$3,2,0) -> SWEDEN | L49: =INDEX(LOCATION!$A$1:$M$1,1,MATCH($J49,LOCATION!$A$2:$M$2,0)) -> Swedish | M49: =_xlfn.CONCAT(F49,".",D49,"@xyz",IF(L49="English","org",".com")) -> Soderberg.Mirjam@xyz.com | N49: 50 | O49: Amber | P49: O+ | Q49: =_xlfn.XLOOKUP($R49,SPORT!$B$1:$B$33,SPORT!$A$1:$A$33) -> OUTDOOR | R49: Football | S49: 38965 | T49: =UPPER(B49) -> FRU. MIRJAM SODERBERG | U49: 48 | V49: 35567 | W49: 50 | X49: 38965
A50: 49 | B50: =UPPER(_xlfn.CONCAT(C50," ",D50," ",F50)) -> H. BERNDT PALSSON | C50: H. | D50: Berndt | F50: Palsson | G50: 31832 | H50: Pisces | I50: Male | J50: SV | K50: =HLOOKUP($J50,LOCATION!$A$2:$M$3,2,0) -> SWEDEN | L50: =INDEX(LOCATION!$A$1:$M$1,1,MATCH($J50,LOCATION!$A$2:$M$2,0)) -> Swedish | M50: =_xlfn.CONCAT(F50,".",D50,"@xyz",IF(L50="English","org",".com")) -> Palsson.Berndt@xyz.com | N50: 45.9 | O50: Blue | P50: A− | Q50: =_xlfn.XLOOKUP($R50,SPORT!$B$1:$B$33,SPORT!$A$1:$A$33) -> OUTDOOR | R50: Biathlon | S50: 35387 | T50: =UPPER(B50) -> H. BERNDT PALSSON | U50: 49 | V50: 31832 | W50: 45.9 | X50: 35387
A51: 50 | B51: =UPPER(_xlfn.CONCAT(C51," ",D51," ",F51)) -> SR. ADRIANO SOBRINHO | C51: Sr. | D51: Adriano | E51: Pontes | F51: Sobrinho | G51: 34178 | H51: Leo | I51: Male | J51: PR | K51: =HLOOKUP($J51,LOCATION!$A$2:$M$3,2,0) -> BRAZIL | L51: =INDEX(LOCATION!$A$1:$M$1,1,MATCH($J51,LOCATION!$A$2:$M$2,0)) -> Portuguese | M51: =_xlfn.CONCAT(F51,".",D51,"@xyz",IF(L51="English","org",".com")) -> Sobrinho.Adriano@xyz.com | N51: 92.5 | O51: Green | P51: A+ | Q51: =_xlfn.XLOOKUP($R51,SPORT!$B$1:$B$33,SPORT!$A$1:$A$33) -> INDOOR | R51: Swimming | S51: 20532 | T51: =UPPER(B51) -> SR. ADRIANO SOBRINHO | U51: 50 | V51: 34178 | W51: 92.5 | X51: 20532

Sheet SPORT
A1: SPORTS LOCATION | B1: SPORTS
A2: INDOOR | B2: Cycling Track
A3: INDOOR | B3: Boxing
A4: OUTDOOR | B4: Football
A5: OUTDOOR | B5: Alpine Skiing
A6: INDOOR | B6: Water Polo
A7: INDOOR | B7: Fencing
A8: OUTDOOR | B8: Cycling Road
A9: INDOOR | B9: Curling
A10: INDOOR | B10: Shooting
A11: OUTDOOR | B11: Freestyle Skiing
A12: OUTDOOR | B12: Archery
... A33: INDOOR | B33: Swimming

Sheet LOCATION
A1: LANGUAGE | B1: English | C1: Portuguese | D1: English | E1: German | F1: English | G1: German | H1: French | I1: Spanish | J1: Spanish | K1: Dutch | L1: Swedish | M1: Portuguese
A2: COUNTRYCODE | B2: US | C2: BR | D2: GB | E2: DE | F2: OZ | G2: AU | H2: FR | I2: AG | J2: ES | K2: DU | L2: SV | M2: PR
A3: COUNTRY NAME | B3: USA | C3: BRAZIL | D3: UK | E3: GERMANY | F3: AUSTRALIA | G3: AUSTRIA | H3: FRANCE | I3: ARGENTINA | J3: SPAIN | K3: NETHERLANDS | L3: SWEDEN | M3: BRAZIL
